Workbook

Sheet Evaluation
A1: No | B1: Category | C1: Prompt | D1: AI | E1: Relevance | F1: Clarity | G1: Completeness | H1: Factual Accuracy | I1: Grammar & Language | J1: Average | K1: Justification
A2: 1 | B2: Health and Life Style | C2: What are the health benefits of regular exercise? | D2: ChatGPT | E2: 5 | F2: 5 | G2: 5 | H2: 5 | I2: 5 | J2: =AVERAGE(E2:I2) -> 5 | K2: The response directly answers the question with excellent organization and covers all major physical and mental health benefits. The information is accurate, balanced, and written in clear, natural English
D3: Gemini | E3: 5 | F3: 4 | G3: 5 | H3: 5 | I3: 5 | J3: =AVERAGE(E3:I3) -> 4.8 | K3: The response is comprehensive and scientifically accurate. However, some explanations are more technical and slightly longer than necessary, making the response a bit less easy to read.
D4: Copilot | E4: 5 | F4: 5 | G4: 4 | H4: 5 | I4: 5 | J4: =AVERAGE(E4:I4) -> 4.8 | K4: The response is relevant and easy to understand. It includes the main health benefits, but some supporting details are less comprehensive than the other responses.
A5: 2 | B5: Health and Life Style | C5: How can I build and maintain a healthy sleep schedule? | D5: ChatGPT | E5: 5 | F5: 5 | G5: 5 | H5: 5 | I5: 5 | J5: =AVERAGE(E5:I5) -> 5 | K5: The response provides practical, well-structured advice supported by established sleep recommendations. It is comprehensive, easy to follow, and written in fluent English.
D6: Gemini | E6: 5 | F6: 4 | G6: 5 | H6: 5 | I6: 5 | J6: =AVERAGE(E6:I6) -> 4.8 | K6: The response is highly informative and scientifically sound. Some sections include more technical explanations than necessary, which slightly reduces readability.
D7: Copilot | E7: 5 | F7: 5 | G7: 5 | H7: 5 | I7: 5 | J7: =AVERAGE(E7:I7) -> 5 | K7: The response is clear, practical, and complete. It presents actionable advice in a logical structure while maintaining accurate information and natural language.
A8: 3 | B8: Health and Life Style | C8: What are the main causes of high blood pressure? | D8: ChatGPT | E8: 5 | F8: 5 | G8: 5 | H8: 5 | I8: 5 | J8: =AVERAGE(E8:I8) -> 5 | K8: The response clearly explains both primary and secondary causes of hypertension with accurate medical information. It is well organized and easy to understand.
D9: Gemini | E9: 5 | F9: 5 | G9: 5 | H9: 5 | I9: 5 | J9: =AVERAGE(E9:I9) -> 5 | K9: The response is detailed, logically organized, and explains the underlying mechanisms behind hypertension. The information is accurate and presented in fluent English.
D10: Copilot | E10: 5 | F10: 4 | G10: 5 | H10: 5 | I10: 5 | J10: =AVERAGE(E10:I10) -> 4.8 | K10: The response provides accurate information and includes useful examples. However, the inclusion of lengthy reference material makes the answer slightly less concise and harder to follow.
A11: 4 | B11: Health and Life Style | C11: Why is staying hydrated so important for our body? | D11: ChatGPT | E11: 5 | F11: 5 | G11: 5 | H11: 5 | I11: 5 | J11: =AVERAGE(E11:I11) -> 5 | K11: The response thoroughly explains the importance of hydration using clear language and accurate health information. It also provides practical hydration advice.
D12: Gemini | E12: 5 | F12: 5 | G12: 5 | H12: 5 | I12: 5 | J12: =AVERAGE(E12:I12) -> 5 | K12: The response combines scientific explanations with practical guidance in a clear and engaging way. It is complete, accurate, and easy to understand.
D13: Copilot | E13: 5 | F13: 5 | G13: 4 | H13: 5 | I13: 5 | J13: =AVERAGE(E13:I13) -> 4.8 | K13: The response covers the essential functions of hydration and provides useful recommendations. Some explanations are less detailed than the other responses.
A14: 5 | B14: Health and Life Style | C14: What are the best ways to manage stress? | D14: ChatGPT | E14: 5 | F14: 5 | G14: 5 | H14: 5 | I14: 5 | J14: =AVERAGE(E14:I14) -> 5 | K14: The response provides practical, evidence-based strategies with a clear structure and balanced recommendations. It is comprehensive and written in natural English.
D15: Gemini | E15: 5 | F15: 5 | G15: 5 | H15: 5 | I15: 5 | J15: =AVERAGE(E15:I15) -> 5 | K15: The response explains both immediate and long-term stress management techniques in a logical and engaging way. It is accurate, complete, and easy to follow.
D16: Copilot | E16: 5 | F16: 5 | G16: 4 | H16: 5 | I16: 5 | J16: =AVERAGE(E16:I16) -> 4.8 | K16: The response includes the main stress management strategies and presents them clearly. While informative, it provides slightly less depth than the other responses.
A17: 6 | B17: Health and Life Style | C17: What are the benefits of working out in the morning? | D17: ChatGPT | E17: 5 | F17: 5 | G17: 5 | H17: 5 | I17: 5 | J17: =AVERAGE(E17:I17) -> 5 | K17: The response fully answers the question with a balanced discussion of benefits and potential drawbacks. It is well organized, factually accurate, and written in clear, natural English.
D18: Gemini | E18: 5 | F18: 5 | G18: 5 | H18: 5 | I18: 5 | J18: =AVERAGE(E18:I18) -> 5 | K18: The response explains the physiological reasons behind morning exercise while remaining easy to understand. The information is accurate, engaging, and comprehensive.
D19: Copilot | E19: 5 | F19: 5 | G19: 5 | H19: 5 | I19: 5 | J19: =AVERAGE(E19:I19) -> 5 | K19: The response is informative, practical, and well structured. It covers both health benefits and local considerations without sacrificing clarity or accuracy.
A20: 7 | B20: Education and Self-Development | C20: What are the benefits of reading? | D20: ChatGPT | E20: 5 | F20: 5 | G20: 5 | H20: 5 | I20: 5 | J20: =AVERAGE(E20:I20) -> 5 | K20: The response provides a complete overview of reading benefits with excellent organization and easy-to-understand language. The information is accurate and practical.
D21: Gemini | E21: 5 | F21: 5 | G21: 5 | H21: 5 | I21: 5 | J21: =AVERAGE(E21:I21) -> 5 | K21: The response combines scientific evidence with practical examples in a clear and engaging way. It is comprehensive, well written, and easy to follow.
D22: Copilot | E22: 5 | F22: 5 | G22: 5 | H22: 4 | I22: 5 | J22: =AVERAGE(E22:I22) -> 4.8 | K22: The response is relevant and clearly organized. However, one or two research-based claims are presented with stronger certainty than the available evidence fully supports, slightly reducing factual accuracy.
A23: 8 | B23: Education and Self-Development | C23: How can I learn English faster? | D23: ChatGPT | E23: 5 | F23: 5 | G23: 5 | H23: 5 | I23: 5 | J23: =AVERAGE(E23:I23) -> 5 | K23: The response offers a practical learning plan with actionable daily activities. It is comprehensive, well structured, and tailored to the user's goals.
D24: Gemini | E24: 5 | F24: 5 | G24: 5 | H24: 5 | I24: 5 | J24: =AVERAGE(E24:I24) -> 5 | K24: The response explains effective language-learning strategies with clear reasoning and useful examples. It is complete, accurate, and written in natural English.
D25: Copilot | E25: 5 | F25: 5 | G25: 4 | H25: 5 | I25: 5 | J25: =AVERAGE(E25:I25) -> 4.8 | K25: The response provides useful and practical learning strategies in a clear format. Although informative, it offers slightly fewer detailed techniques than the other responses.
A26: 9 | B26: Education and Self-Development | C26: Why is math so important in daily life? | D26: ChatGPT | E26: 5 | F26: 5 | G26: 5 | H26: 5 | I26: 5 | J26: =AVERAGE(E26:I26) -> 5 | K26: The response explains the importance of mathematics through practical everyday examples. It is comprehensive, easy to understand, and factually accurate.
D27: Gemini | E27: 5 | F27: 5 | G27: 5 | H27: 5 | I27: 5 | J27: =AVERAGE(E27:I27) -> 5 | K27: The response connects mathematical thinking with real-life applications while emphasizing logical reasoning. It is well organized, complete, and written in fluent English.
D28: Copilot | E28: 5 | F28: 5 | G28: 5 | H28: 5 | I28: 5 | J28: =AVERAGE(E28:I28) -> 5 | K28: The response clearly demonstrates how math applies to everyday life through practical examples. It is accurate, well structured, and easy to read.
A29: 10 | B29: Education and Self-Development | C29: How can I manage my time more effectively? | D29: ChatGPT | E29: 5 | F29: 5 | G29: 5 | H29: 5 | I29: 5 | J29: =AVERAGE(E29:I29) -> 5 | K29: The response presents practical time-management techniques in a logical sequence with clear explanations. It is comprehensive, accurate, and easy to apply.
D30: Gemini | E30: 5 | F30: 5 | G30: 5 | H30: 5 | I30: 5 | J30: =AVERAGE(E30:I30) -> 5 | K30: The response explains proven productivity methods with useful context and practical advice. It is complete, well organized, and written in natural English.
D31: Copilot | E31: 5 | F31: 5 | G31: 5 | H31: 5 | I31: 5 | J31: =AVERAGE(E31:I31) -> 5 | K31: The response covers the essential time-management strategies in a clear and structured manner. The advice is practical, accurate, and supported by well-known productivity techniques.
A32: 11 | B32: Business and Management | C32: How can I increase sales for a grocery store? | D32: ChatGPT | E32: 5 | F32: 5 | G32: 5 | H32: 5 | I32: 5 | J32: =AVERAGE(E32:I32) -> 5 | K32: The response provides practical and actionable strategies covering pricing, customer service, inventory, promotions, and store layout. It is comprehensive, well organized, and easy to understand.
D33: Gemini | E33: 5 | F33: 5 | G33: 5 | H33: 5 | I33: 5 | J33: =AVERAGE(E33:I33) -> 5 | K33: The response combines business strategy with clear explanations and practical examples. It is well structured, factually sound, and offers useful recommendations for improving sales.
D34: Copilot | E34: 5 | F34: 5 | G34: 4 | H34: 5 | I34: 5 | J34: =AVERAGE(E34:I34) -> 4.8 | K34: The response answers the question clearly with relevant suggestions. However, it provides slightly less detail on long-term business strategies than the other responses.
A35: 12 | B35: Business and Management | C35: Why is good customer service so important? | D35: ChatGPT | E35: 5 | F35: 5 | G35: 5 | H35: 5 | I35: 5 | J35: =AVERAGE(E35:I35) -> 5 | K35: The response clearly explains how customer service affects customer satisfaction, loyalty, and business growth. It is complete, accurate, and written in natural English.
D36: Gemini | E36: 5 | F36: 5 | G36: 5 | H36: 5 | I36: 5 | J36: =AVERAGE(E36:I36) -> 5 | K36: The response presents both business and customer perspectives while maintaining excellent clarity. It is informative, engaging, and supported by practical examples.
D37: Copilot | E37: 5 | F37: 5 | G37: 5 | H37: 5 | I37: 5 | J37: =AVERAGE(E37:I37) -> 5 | K37: The response provides a well-balanced explanation of the importance of customer service. The information is accurate, relevant, and presented in a logical structure.
A38: 13 | B38: Business and Management | C38: What are the best practices for inventory management? | D38: ChatGPT | E38: 5 | F38: 5 | G38: 5 | H38: 5 | I38: 5 | J38: =AVERAGE(E38:I38) -> 5 | K38: The response covers key inventory management practices, including stock monitoring, forecasting, and inventory control methods. It is comprehensive and practical.
D39: Gemini | E39: 5 | F39: 5 | G39: 5 | H39: 5 | I39: 5 | J39: =AVERAGE(E39:I39) -> 5 | K39: The response explains inventory management principles in a logical and detailed manner. It provides useful recommendations that are both practical and factually accurate.
D40: Copilot | E40: 5 | F40: 5 | G40: 4 | H40: 5 | I40: 5 | J40: =AVERAGE(E40:I40) -> 4.8 | K40: The response includes the essential inventory management techniques in a clear format. While accurate, it does not discuss forecasting and optimization in as much depth as the other responses.
...

Sheet Result
B1: Average
A2: AI | B2: Relevance | C2: Clarity | D2: Completeness | E2: Factual Accuracy | F2: Grammar & Language | G2: Result Average
A3: ChatGPT | B3: =AVERAGEIF(Evaluation!D2:D61, "ChatGPT", Evaluation!E2:E61) -> 5 | C3: =AVERAGEIF(Evaluation!D2:D61, "ChatGPT", Evaluation!F2:F61) -> 5 | D3: =AVERAGEIF(Evaluation!D2:D61, "ChatGPT", Evaluation!G2:G61) -> 5 | E3: =AVERAGEIF(Evaluation!D2:D61, "ChatGPT", Evaluation!H2:H61) -> 5 | F3: =AVERAGEIF(Evaluation!D2:D61, "ChatGPT", Evaluation!I2:I61) -> 5 | G3: =AVERAGEIF(Evaluation!D2:D61, "ChatGPT", Evaluation!J2:J61) -> 5
A4: Gemini | B4: =AVERAGEIF(Evaluation!D2:D61, "Gemini", Evaluation!E2:E61) -> 5 | C4: =AVERAGEIF(Evaluation!D2:D61, "Gemini", Evaluation!F2:F61) -> 4.85 | D4: =AVERAGEIF(Evaluation!D2:D61, "Gemini", Evaluation!G2:G61) -> 5 | E4: =AVERAGEIF(Evaluation!D2:D61, "Gemini", Evaluation!H2:H61) -> 5 | F4: =AVERAGEIF(Evaluation!D2:D61, "Gemini", Evaluation!I2:I61) -> 5 | G4: =AVERAGEIF(Evaluation!D2:D61, "Gemini", Evaluation!J2:J61) -> 4.97
A5: Copilot | B5: =AVERAGEIF(Evaluation!D2:D61, "Copilot", Evaluation!E2:E61) -> 5 | C5: =AVERAGEIF(Evaluation!D2:D61, "Copilot", Evaluation!F2:F61) -> 4.95 | D5: =AVERAGEIF(Evaluation!D2:D61, "Copilot", Evaluation!G2:G61) -> 4.65 | E5: =AVERAGEIF(Evaluation!D2:D61, "Copilot", Evaluation!H2:H61) -> 4.95 | F5: =AVERAGEIF(Evaluation!D2:D61, "Copilot", Evaluation!I2:I61) -> 5 | G5: =AVERAGEIF(Evaluation!D2:D61, "Copilot", Evaluation!J2:J61) -> 4.91
